[2024-05-03T21:56:11.452+0000] {taskinstance.py:1103} INFO - Dependencies all met for dep_context=non-requeueable deps ti=<TaskInstance: demo.read_csv scheduled__2022-01-09T00:00:00+00:00 [queued]>
[2024-05-03T21:56:11.692+0000] {taskinstance.py:1103} INFO - Dependencies all met for dep_context=requeueable deps ti=<TaskInstance: demo.read_csv scheduled__2022-01-09T00:00:00+00:00 [queued]>
[2024-05-03T21:56:11.693+0000] {taskinstance.py:1308} INFO - Starting attempt 1 of 1
[2024-05-03T21:56:12.131+0000] {taskinstance.py:1327} INFO - Executing <Task(_PythonDecoratedOperator): read_csv> on 2022-01-09 00:00:00+00:00
[2024-05-03T21:56:12.321+0000] {standard_task_runner.py:57} INFO - Started process 704 to run task
[2024-05-03T21:56:12.345+0000] {standard_task_runner.py:84} INFO - Running: ['***', 'tasks', 'run', 'demo', 'read_csv', 'scheduled__2022-01-09T00:00:00+00:00', '--job-id', '159', '--raw', '--subdir', 'DAGS_FOLDER/dag_trial.py', '--cfg-path', '/tmp/tmp97_a2isi']
[2024-05-03T21:56:12.375+0000] {standard_task_runner.py:85} INFO - Job 159: Subtask read_csv
[2024-05-03T21:56:13.572+0000] {task_command.py:410} INFO - Running <TaskInstance: demo.read_csv scheduled__2022-01-09T00:00:00+00:00 [running]> on host 08fc968d0c14
[2024-05-03T21:56:15.577+0000] {taskinstance.py:1547} INFO - Exporting env vars: AIRFLOW_CTX_DAG_OWNER='***' AIRFLOW_CTX_DAG_ID='demo' AIRFLOW_CTX_TASK_ID='read_csv' AIRFLOW_CTX_EXECUTION_DATE='2022-01-09T00:00:00+00:00' AIRFLOW_CTX_TRY_NUMBER='1' AIRFLOW_CTX_DAG_RUN_ID='scheduled__2022-01-09T00:00:00+00:00'
[2024-05-03T21:56:15.584+0000] {taskinstance.py:1824} ERROR - Task failed with exception
Traceback (most recent call last):
  File "/home/airflow/.local/lib/python3.7/site-packages/airflow/decorators/base.py", line 220, in execute
    return_value = super().execute(context)
  File "/home/airflow/.local/lib/python3.7/site-packages/airflow/operators/python.py", line 181, in execute
    return_value = self.execute_callable()
  File "/home/airflow/.local/lib/python3.7/site-packages/airflow/operators/python.py", line 198, in execute_callable
    return self.python_callable(*self.op_args, **self.op_kwargs)
  File "/opt/airflow/dags/dag_trial.py", line 19, in read_csv
    df = pd.read_csv('path/to/your/file.csv')
  File "/home/airflow/.local/lib/python3.7/site-packages/pandas/util/_decorators.py", line 311, in wrapper
    return func(*args, **kwargs)
  File "/home/airflow/.local/lib/python3.7/site-packages/pandas/io/parsers/readers.py", line 586, in read_csv
    return _read(filepath_or_buffer, kwds)
  File "/home/airflow/.local/lib/python3.7/site-packages/pandas/io/parsers/readers.py", line 482, in _read
    parser = TextFileReader(filepath_or_buffer, **kwds)
  File "/home/airflow/.local/lib/python3.7/site-packages/pandas/io/parsers/readers.py", line 811, in __init__
    self._engine = self._make_engine(self.engine)
  File "/home/airflow/.local/lib/python3.7/site-packages/pandas/io/parsers/readers.py", line 1040, in _make_engine
    return mapping[engine](self.f, **self.options)  # type: ignore[call-arg]
  File "/home/airflow/.local/lib/python3.7/site-packages/pandas/io/parsers/c_parser_wrapper.py", line 51, in __init__
    self._open_handles(src, kwds)
  File "/home/airflow/.local/lib/python3.7/site-packages/pandas/io/parsers/base_parser.py", line 229, in _open_handles
    errors=kwds.get("encoding_errors", "strict"),
  File "/home/airflow/.local/lib/python3.7/site-packages/pandas/io/common.py", line 707, in get_handle
    newline="",
FileNotFoundError: [Errno 2] No such file or directory: 'path/to/your/file.csv'
[2024-05-03T21:56:15.670+0000] {taskinstance.py:1350} INFO - Marking task as FAILED. dag_id=demo, task_id=read_csv, execution_date=20220109T000000, start_date=20240503T215611, end_date=20240503T215615
[2024-05-03T21:56:15.908+0000] {standard_task_runner.py:109} ERROR - Failed to execute job 159 for task read_csv ([Errno 2] No such file or directory: 'path/to/your/file.csv'; 704)
[2024-05-03T21:56:16.115+0000] {local_task_job_runner.py:225} INFO - Task exited with return code 1
[2024-05-03T21:56:16.315+0000] {taskinstance.py:2651} INFO - 0 downstream tasks scheduled from follow-on schedule check
