[2024-05-03T00:08:14.923+0000] {taskinstance.py:1103} INFO - Dependencies all met for dep_context=non-requeueable deps ti=<TaskInstance: test_dag.get_track_data manual__2024-05-03T00:08:10.317286+00:00 [queued]>
[2024-05-03T00:08:14.961+0000] {taskinstance.py:1103} INFO - Dependencies all met for dep_context=requeueable deps ti=<TaskInstance: test_dag.get_track_data manual__2024-05-03T00:08:10.317286+00:00 [queued]>
[2024-05-03T00:08:14.962+0000] {taskinstance.py:1308} INFO - Starting attempt 1 of 1
[2024-05-03T00:08:15.027+0000] {taskinstance.py:1327} INFO - Executing <Task(PythonOperator): get_track_data> on 2024-05-03 00:08:10.317286+00:00
[2024-05-03T00:08:15.043+0000] {standard_task_runner.py:57} INFO - Started process 187 to run task
[2024-05-03T00:08:15.056+0000] {standard_task_runner.py:84} INFO - Running: ['***', 'tasks', 'run', 'test_dag', 'get_track_data', 'manual__2024-05-03T00:08:10.317286+00:00', '--job-id', '105', '--raw', '--subdir', 'DAGS_FOLDER/test_dag.py', '--cfg-path', '/tmp/tmpz8sv8nzh']
[2024-05-03T00:08:15.059+0000] {standard_task_runner.py:85} INFO - Job 105: Subtask get_track_data
[2024-05-03T00:08:15.185+0000] {task_command.py:410} INFO - Running <TaskInstance: test_dag.get_track_data manual__2024-05-03T00:08:10.317286+00:00 [running]> on host 08fc968d0c14
[2024-05-03T00:08:15.477+0000] {taskinstance.py:1547} INFO - Exporting env vars: AIRFLOW_CTX_DAG_OWNER='***' AIRFLOW_CTX_DAG_ID='test_dag' AIRFLOW_CTX_TASK_ID='get_track_data' AIRFLOW_CTX_EXECUTION_DATE='2024-05-03T00:08:10.317286+00:00' AIRFLOW_CTX_TRY_NUMBER='1' AIRFLOW_CTX_DAG_RUN_ID='manual__2024-05-03T00:08:10.317286+00:00'
[2024-05-03T00:08:15.508+0000] {base.py:73} INFO - Using connection ID '***' for task execution.
[2024-05-03T00:08:15.514+0000] {taskinstance.py:1824} ERROR - Task failed with exception
Traceback (most recent call last):
  File "/home/airflow/.local/lib/python3.7/site-packages/airflow/operators/python.py", line 181, in execute
    return_value = self.execute_callable()
  File "/home/airflow/.local/lib/python3.7/site-packages/airflow/operators/python.py", line 198, in execute_callable
    return self.python_callable(*self.op_args, **self.op_kwargs)
  File "/opt/airflow/dags/test_dag.py", line 23, in get_track_data
    pg_conn = pg_hook.get_conn()
  File "/home/airflow/.local/lib/python3.7/site-packages/airflow/providers/postgres/hooks/postgres.py", line 144, in get_conn
    self.conn = psycopg2.connect(**conn_args)
  File "/home/airflow/.local/lib/python3.7/site-packages/psycopg2/__init__.py", line 122, in connect
    conn = _connect(dsn, connection_factory=connection_factory, **kwasync)
psycopg2.OperationalError: connection to server at "localhost" (::1), port 5432 failed: Connection refused
	Is the server running on that host and accepting TCP/IP connections?
connection to server at "localhost" (127.0.0.1), port 5432 failed: Connection refused
	Is the server running on that host and accepting TCP/IP connections?

[2024-05-03T00:08:15.543+0000] {taskinstance.py:1350} INFO - Marking task as FAILED. dag_id=test_dag, task_id=get_track_data, execution_date=20240503T000810, start_date=20240503T000814, end_date=20240503T000815
[2024-05-03T00:08:15.593+0000] {standard_task_runner.py:109} ERROR - Failed to execute job 105 for task get_track_data (connection to server at "localhost" (::1), port 5432 failed: Connection refused
	Is the server running on that host and accepting TCP/IP connections?
connection to server at "localhost" (127.0.0.1), port 5432 failed: Connection refused
	Is the server running on that host and accepting TCP/IP connections?
; 187)
[2024-05-03T00:08:15.644+0000] {local_task_job_runner.py:225} INFO - Task exited with return code 1
[2024-05-03T00:08:15.746+0000] {taskinstance.py:2651} INFO - 0 downstream tasks scheduled from follow-on schedule check
