[2024-05-03T00:01:37.682+0000] {taskinstance.py:1103} INFO - Dependencies all met for dep_context=non-requeueable deps ti=<TaskInstance: test_dag.get_track_data manual__2024-05-03T00:01:33.436220+00:00 [queued]>
[2024-05-03T00:01:37.708+0000] {taskinstance.py:1103} INFO - Dependencies all met for dep_context=requeueable deps ti=<TaskInstance: test_dag.get_track_data manual__2024-05-03T00:01:33.436220+00:00 [queued]>
[2024-05-03T00:01:37.708+0000] {taskinstance.py:1308} INFO - Starting attempt 1 of 1
[2024-05-03T00:01:37.755+0000] {taskinstance.py:1327} INFO - Executing <Task(PythonOperator): get_track_data> on 2024-05-03 00:01:33.436220+00:00
[2024-05-03T00:01:37.768+0000] {standard_task_runner.py:57} INFO - Started process 64 to run task
[2024-05-03T00:01:37.776+0000] {standard_task_runner.py:84} INFO - Running: ['***', 'tasks', 'run', 'test_dag', 'get_track_data', 'manual__2024-05-03T00:01:33.436220+00:00', '--job-id', '102', '--raw', '--subdir', 'DAGS_FOLDER/test_dag.py', '--cfg-path', '/tmp/tmpxm7hxwlm']
[2024-05-03T00:01:37.782+0000] {standard_task_runner.py:85} INFO - Job 102: Subtask get_track_data
[2024-05-03T00:01:37.895+0000] {task_command.py:410} INFO - Running <TaskInstance: test_dag.get_track_data manual__2024-05-03T00:01:33.436220+00:00 [running]> on host 08fc968d0c14
[2024-05-03T00:01:38.170+0000] {taskinstance.py:1547} INFO - Exporting env vars: AIRFLOW_CTX_DAG_OWNER='***' AIRFLOW_CTX_DAG_ID='test_dag' AIRFLOW_CTX_TASK_ID='get_track_data' AIRFLOW_CTX_EXECUTION_DATE='2024-05-03T00:01:33.436220+00:00' AIRFLOW_CTX_TRY_NUMBER='1' AIRFLOW_CTX_DAG_RUN_ID='manual__2024-05-03T00:01:33.436220+00:00'
[2024-05-03T00:01:38.226+0000] {taskinstance.py:1824} ERROR - Task failed with exception
Traceback (most recent call last):
  File "/home/airflow/.local/lib/python3.7/site-packages/airflow/operators/python.py", line 181, in execute
    return_value = self.execute_callable()
  File "/home/airflow/.local/lib/python3.7/site-packages/airflow/operators/python.py", line 198, in execute_callable
    return self.python_callable(*self.op_args, **self.op_kwargs)
  File "/opt/airflow/dags/test_dag.py", line 12, in get_track_data
    pg_conn = pg_hook.get_conn()
  File "/home/airflow/.local/lib/python3.7/site-packages/airflow/providers/postgres/hooks/postgres.py", line 117, in get_conn
    conn = deepcopy(self.connection or self.get_connection(conn_id))
  File "/home/airflow/.local/lib/python3.7/site-packages/airflow/hooks/base.py", line 72, in get_connection
    conn = Connection.get_connection_from_secrets(conn_id)
  File "/home/airflow/.local/lib/python3.7/site-packages/airflow/models/connection.py", line 434, in get_connection_from_secrets
    raise AirflowNotFoundException(f"The conn_id `{conn_id}` isn't defined")
airflow.exceptions.AirflowNotFoundException: The conn_id `test_dag` isn't defined
[2024-05-03T00:01:38.240+0000] {taskinstance.py:1350} INFO - Marking task as FAILED. dag_id=test_dag, task_id=get_track_data, execution_date=20240503T000133, start_date=20240503T000137, end_date=20240503T000138
[2024-05-03T00:01:38.276+0000] {standard_task_runner.py:109} ERROR - Failed to execute job 102 for task get_track_data (The conn_id `test_dag` isn't defined; 64)
[2024-05-03T00:01:38.316+0000] {local_task_job_runner.py:225} INFO - Task exited with return code 1
[2024-05-03T00:01:38.385+0000] {taskinstance.py:2651} INFO - 0 downstream tasks scheduled from follow-on schedule check
