[2024-05-04T15:54:12.849+0000] {taskinstance.py:1103} INFO - Dependencies all met for dep_context=non-requeueable deps ti=<TaskInstance: data_traffic_ingestion.extract_data manual__2024-05-04T15:54:07.046755+00:00 [queued]>
[2024-05-04T15:54:12.943+0000] {taskinstance.py:1103} INFO - Dependencies all met for dep_context=requeueable deps ti=<TaskInstance: data_traffic_ingestion.extract_data manual__2024-05-04T15:54:07.046755+00:00 [queued]>
[2024-05-04T15:54:12.944+0000] {taskinstance.py:1308} INFO - Starting attempt 1 of 1
[2024-05-04T15:54:13.252+0000] {taskinstance.py:1327} INFO - Executing <Task(PythonOperator): extract_data> on 2024-05-04 15:54:07.046755+00:00
[2024-05-04T15:54:13.533+0000] {standard_task_runner.py:84} INFO - Running: ['***', 'tasks', 'run', 'data_traffic_ingestion', 'extract_data', 'manual__2024-05-04T15:54:07.046755+00:00', '--job-id', '1412', '--raw', '--subdir', 'DAGS_FOLDER/final_dag.py', '--cfg-path', '/tmp/tmpm1uthqwe']
[2024-05-04T15:54:13.536+0000] {standard_task_runner.py:85} INFO - Job 1412: Subtask extract_data
[2024-05-04T15:54:13.451+0000] {standard_task_runner.py:57} INFO - Started process 11190 to run task
[2024-05-04T15:54:14.257+0000] {task_command.py:410} INFO - Running <TaskInstance: data_traffic_ingestion.extract_data manual__2024-05-04T15:54:07.046755+00:00 [running]> on host 08fc968d0c14
[2024-05-04T15:54:15.142+0000] {taskinstance.py:1547} INFO - Exporting env vars: AIRFLOW_CTX_DAG_OWNER='***' AIRFLOW_CTX_DAG_ID='data_traffic_ingestion' AIRFLOW_CTX_TASK_ID='extract_data' AIRFLOW_CTX_EXECUTION_DATE='2024-05-04T15:54:07.046755+00:00' AIRFLOW_CTX_TRY_NUMBER='1' AIRFLOW_CTX_DAG_RUN_ID='manual__2024-05-04T15:54:07.046755+00:00'
[2024-05-04T15:54:15.174+0000] {taskinstance.py:1824} ERROR - Task failed with exception
Traceback (most recent call last):
  File "/home/airflow/.local/lib/python3.7/site-packages/airflow/operators/python.py", line 181, in execute
    return_value = self.execute_callable()
  File "/home/airflow/.local/lib/python3.7/site-packages/airflow/operators/python.py", line 198, in execute_callable
    return self.python_callable(*self.op_args, **self.op_kwargs)
  File "/opt/airflow/dags/scripts/load.py", line 42, in extract_data
    file_path=self.read_dag_path, v=0)
  File "dags/scripts/data_reader.py", line 104, in get_dfs
    lines = self.read_file(file_path)
  File "dags/scripts/data_reader.py", line 24, in read_file
    with open(path, 'r') as f:
FileNotFoundError: [Errno 2] No such file or directory: './data/20181029_d1_0900_0930.csv'
[2024-05-04T15:54:15.274+0000] {taskinstance.py:1350} INFO - Marking task as FAILED. dag_id=data_traffic_ingestion, task_id=extract_data, execution_date=20240504T155407, start_date=20240504T155412, end_date=20240504T155415
[2024-05-04T15:54:15.355+0000] {standard_task_runner.py:109} ERROR - Failed to execute job 1412 for task extract_data ([Errno 2] No such file or directory: './data/20181029_d1_0900_0930.csv'; 11190)
[2024-05-04T15:54:15.399+0000] {local_task_job_runner.py:225} INFO - Task exited with return code 1
[2024-05-04T15:54:15.533+0000] {taskinstance.py:2651} INFO - 0 downstream tasks scheduled from follow-on schedule check
