[2024-05-02T22:03:31.365+0000] {taskinstance.py:1103} INFO - Dependencies all met for dep_context=non-requeueable deps ti=<TaskInstance: test_dag.get_iris_data manual__2024-05-02T22:03:26.509072+00:00 [queued]>
[2024-05-02T22:03:31.405+0000] {taskinstance.py:1103} INFO - Dependencies all met for dep_context=requeueable deps ti=<TaskInstance: test_dag.get_iris_data manual__2024-05-02T22:03:26.509072+00:00 [queued]>
[2024-05-02T22:03:31.405+0000] {taskinstance.py:1308} INFO - Starting attempt 1 of 1
[2024-05-02T22:03:31.494+0000] {taskinstance.py:1327} INFO - Executing <Task(PythonOperator): get_iris_data> on 2024-05-02 22:03:26.509072+00:00
[2024-05-02T22:03:31.511+0000] {standard_task_runner.py:57} INFO - Started process 100 to run task
[2024-05-02T22:03:31.543+0000] {standard_task_runner.py:84} INFO - Running: ['***', 'tasks', 'run', 'test_dag', 'get_iris_data', 'manual__2024-05-02T22:03:26.509072+00:00', '--job-id', '93', '--raw', '--subdir', 'DAGS_FOLDER/test_dag.py', '--cfg-path', '/tmp/tmpdxvw016p']
[2024-05-02T22:03:31.544+0000] {standard_task_runner.py:85} INFO - Job 93: Subtask get_iris_data
[2024-05-02T22:03:31.863+0000] {task_command.py:410} INFO - Running <TaskInstance: test_dag.get_iris_data manual__2024-05-02T22:03:26.509072+00:00 [running]> on host 08fc968d0c14
[2024-05-02T22:03:32.235+0000] {taskinstance.py:1547} INFO - Exporting env vars: AIRFLOW_CTX_DAG_OWNER='***' AIRFLOW_CTX_DAG_ID='test_dag' AIRFLOW_CTX_TASK_ID='get_iris_data' AIRFLOW_CTX_EXECUTION_DATE='2024-05-02T22:03:26.509072+00:00' AIRFLOW_CTX_TRY_NUMBER='1' AIRFLOW_CTX_DAG_RUN_ID='manual__2024-05-02T22:03:26.509072+00:00'
[2024-05-02T22:03:32.311+0000] {taskinstance.py:1824} ERROR - Task failed with exception
Traceback (most recent call last):
  File "/home/airflow/.local/lib/python3.7/site-packages/airflow/operators/python.py", line 181, in execute
    return_value = self.execute_callable()
  File "/home/airflow/.local/lib/python3.7/site-packages/airflow/operators/python.py", line 198, in execute_callable
    return self.python_callable(*self.op_args, **self.op_kwargs)
  File "/opt/airflow/dags/test_dag.py", line 17, in get_iris_data
    pg_conn = pg_hook.get_conn()
  File "/home/airflow/.local/lib/python3.7/site-packages/airflow/providers/postgres/hooks/postgres.py", line 117, in get_conn
    conn = deepcopy(self.connection or self.get_connection(conn_id))
  File "/home/airflow/.local/lib/python3.7/site-packages/airflow/hooks/base.py", line 72, in get_connection
    conn = Connection.get_connection_from_secrets(conn_id)
  File "/home/airflow/.local/lib/python3.7/site-packages/airflow/models/connection.py", line 434, in get_connection_from_secrets
    raise AirflowNotFoundException(f"The conn_id `{conn_id}` isn't defined")
airflow.exceptions.AirflowNotFoundException: The conn_id `test_dag` isn't defined
[2024-05-02T22:03:32.322+0000] {taskinstance.py:1350} INFO - Marking task as FAILED. dag_id=test_dag, task_id=get_iris_data, execution_date=20240502T220326, start_date=20240502T220331, end_date=20240502T220332
[2024-05-02T22:03:32.356+0000] {standard_task_runner.py:109} ERROR - Failed to execute job 93 for task get_iris_data (The conn_id `test_dag` isn't defined; 100)
[2024-05-02T22:03:32.383+0000] {local_task_job_runner.py:225} INFO - Task exited with return code 1
[2024-05-02T22:03:32.478+0000] {taskinstance.py:2651} INFO - 0 downstream tasks scheduled from follow-on schedule check
